<?xml version="1.0" ?>
<robot name="another" xmlns:xacro="http://www.ros.org/wiki/xacro">

<xacro:include filename="$(find another_description)/urdf/materials.xacro" />
<xacro:include filename="$(find another_description)/urdf/another.trans" />
<link name="base_link">
  <inertial>
    <origin xyz="0.019733884415405266 0.012767671255082394 0.0010315109673221421" rpy="0 0 0"/>
    <mass value="0.7278674171502194"/>
    <inertia ixx="0.000229" iyy="0.000295" izz="0.000304" ixy="-6e-06" iyz="-2.9e-05" ixz="4e-06"/>
  </inertial>
  <visual>
    <origin xyz="0 0 0" rpy="0 0 0"/>
    <geometry>
      <mesh filename="package://another_description/meshes/base_link.stl" scale="0.001 0.001 0.001"/>
    </geometry>
    <material name="steel_satin"/>
  </visual>
  <collision>
    <origin xyz="0 0 0" rpy="0 0 0"/>
    <geometry>
      <mesh filename="package://another_description/meshes/base_link.stl" scale="0.001 0.001 0.001"/>
    </geometry>
  </collision>
</link>

<link name="new_lower_arm_v6_1">
  <inertial>
    <origin xyz="2.703196100330152e-07 -0.0003831445493740829 0.06000000059604365" rpy="0 0 0"/>
    <mass value="0.11820801114034465"/>
    <inertia ixx="0.000172" iyy="0.000178" izz="6e-06" ixy="0.0" iyz="0.0" ixz="-0.0"/>
  </inertial>
  <visual>
    <origin xyz="-0.030261 -0.04575 -0.01115" rpy="0 0 0"/>
    <geometry>
      <mesh filename="package://another_description/meshes/new_lower_arm_v6_1.stl" scale="0.001 0.001 0.001"/>
    </geometry>
    <material name="steel_satin"/>
  </visual>
  <collision>
    <origin xyz="-0.030261 -0.04575 -0.01115" rpy="0 0 0"/>
    <geometry>
      <mesh filename="package://another_description/meshes/new_lower_arm_v6_1.stl" scale="0.001 0.001 0.001"/>
    </geometry>
  </collision>
</link>

<link name="another_together_v2_1">
  <inertial>
    <origin xyz="-0.006329298038472136 -0.033871597503791484 0.017247108596952998" rpy="0 0 0"/>
    <mass value="0.7593142998563164"/>
    <inertia ixx="0.000885" iyy="0.000906" izz="0.000201" ixy="-1.7e-05" iyz="6.7e-05" ixz="0.000143"/>
  </inertial>
  <visual>
    <origin xyz="-0.030261 -0.04575 -0.13115" rpy="0 0 0"/>
    <geometry>
      <mesh filename="package://another_description/meshes/another_together_v2_1.stl" scale="0.001 0.001 0.001"/>
    </geometry>
    <material name="steel_satin"/>
  </visual>
  <collision>
    <origin xyz="-0.030261 -0.04575 -0.13115" rpy="0 0 0"/>
    <geometry>
      <mesh filename="package://another_description/meshes/another_together_v2_1.stl" scale="0.001 0.001 0.001"/>
    </geometry>
  </collision>
</link>

<link name="another_forearm_v1_1">
  <inertial>
    <origin xyz="0.05291626354016388 0.0040632698862958175 0.0006884554158932688" rpy="0 0 0"/>
    <mass value="0.713224415028411"/>
    <inertia ixx="0.000159" iyy="0.000672" izz="0.000741" ixy="-7.6e-05" iyz="4e-06" ixz="3.1e-05"/>
  </inertial>
  <visual>
    <origin xyz="-0.052261 -0.008302 -0.18775" rpy="0 0 0"/>
    <geometry>
      <mesh filename="package://another_description/meshes/another_forearm_v1_1.stl" scale="0.001 0.001 0.001"/>
    </geometry>
    <material name="steel_satin"/>
  </visual>
  <collision>
    <origin xyz="-0.052261 -0.008302 -0.18775" rpy="0 0 0"/>
    <geometry>
      <mesh filename="package://another_description/meshes/another_forearm_v1_1.stl" scale="0.001 0.001 0.001"/>
    </geometry>
  </collision>
</link>

<link name="lower_arm_pot_v5_1">
  <inertial>
    <origin xyz="1.1084729114881064e-05 -0.06278906355823505 0.05999995404203327" rpy="0 0 0"/>
    <mass value="0.10368770449070258"/>
    <inertia ixx="0.000156" iyy="0.000158" izz="4e-06" ixy="0.0" iyz="0.0" ixz="-0.0"/>
  </inertial>
  <visual>
    <origin xyz="-0.030261 -0.04575 -0.01115" rpy="0 0 0"/>
    <geometry>
      <mesh filename="package://another_description/meshes/lower_arm_pot_v5_1.stl" scale="0.001 0.001 0.001"/>
    </geometry>
    <material name="steel_satin"/>
  </visual>
  <collision>
    <origin xyz="-0.030261 -0.04575 -0.01115" rpy="0 0 0"/>
    <geometry>
      <mesh filename="package://another_description/meshes/lower_arm_pot_v5_1.stl" scale="0.001 0.001 0.001"/>
    </geometry>
  </collision>
</link>

<link name="bottom_v2_1">
  <inertial>
    <origin xyz="0.048721431942784166 0.022326085451289022 -0.01276485359087029" rpy="0 0 0"/>
    <mass value="0.4304093612318312"/>
    <inertia ixx="0.002142" iyy="0.001809" izz="0.000609" ixy="9.7e-05" iyz="-0.000729" ixz="0.000203"/>
  </inertial>
  <visual>
    <origin xyz="-0.1402 0.018693 -0.188247" rpy="0 0 0"/>
    <geometry>
      <mesh filename="package://another_description/meshes/bottom_v2_1.stl" scale="0.001 0.001 0.001"/>
    </geometry>
    <material name="steel_satin"/>
  </visual>
  <collision>
    <origin xyz="-0.1402 0.018693 -0.188247" rpy="0 0 0"/>
    <geometry>
      <mesh filename="package://another_description/meshes/bottom_v2_1.stl" scale="0.001 0.001 0.001"/>
    </geometry>
  </collision>
</link>

<link name="Jaw_top_v27_1">
  <inertial>
    <origin xyz="-1.7811781216625633e-09 0.011351372106049602 -0.005246563597032516" rpy="0 0 0"/>
    <mass value="0.04310244764976378"/>
    <inertia ixx="8e-06" iyy="1e-06" izz="8e-06" ixy="-0.0" iyz="0.0" ixz="0.0"/>
  </inertial>
  <visual>
    <origin xyz="-0.1923 -0.023115 -0.177476" rpy="0 0 0"/>
    <geometry>
      <mesh filename="package://another_description/meshes/Jaw_top_v27_1.stl" scale="0.001 0.001 0.001"/>
    </geometry>
    <material name="steel_satin"/>
  </visual>
  <collision>
    <origin xyz="-0.1923 -0.023115 -0.177476" rpy="0 0 0"/>
    <geometry>
      <mesh filename="package://another_description/meshes/Jaw_top_v27_1.stl" scale="0.001 0.001 0.001"/>
    </geometry>
  </collision>
</link>

<link name="Jaw_top_v23_1">
  <inertial>
    <origin xyz="9.326413427657165e-08 -0.013010663564929446 -0.0028716338111308692" rpy="0 0 0"/>
    <mass value="0.029499910072782735"/>
    <inertia ixx="7e-06" iyy="1e-06" izz="7e-06" ixy="-0.0" iyz="0.0" ixz="-0.0"/>
  </inertial>
  <visual>
    <origin xyz="-0.1923 -0.002064 -0.174863" rpy="0 0 0"/>
    <geometry>
      <mesh filename="package://another_description/meshes/Jaw_top_v23_1.stl" scale="0.001 0.001 0.001"/>
    </geometry>
    <material name="steel_satin"/>
  </visual>
  <collision>
    <origin xyz="-0.1923 -0.002064 -0.174863" rpy="0 0 0"/>
    <geometry>
      <mesh filename="package://another_description/meshes/Jaw_top_v23_1.stl" scale="0.001 0.001 0.001"/>
    </geometry>
  </collision>
</link>

<link name="Left_Claw_v17_1">
  <inertial>
    <origin xyz="0.029512012113970254 0.0014809960971346667 -0.005309409534871301" rpy="0 0 0"/>
    <mass value="0.11917653511717206"/>
    <inertia ixx="1.2e-05" iyy="3.2e-05" izz="2.5e-05" ixy="-4e-06" iyz="-0.0" ixz="0.0"/>
  </inertial>
  <visual>
    <origin xyz="-0.1923 0.034017 -0.178528" rpy="0 0 0"/>
    <geometry>
      <mesh filename="package://another_description/meshes/Left_Claw_v17_1.stl" scale="0.001 0.001 0.001"/>
    </geometry>
    <material name="steel_satin"/>
  </visual>
  <collision>
    <origin xyz="-0.1923 0.034017 -0.178528" rpy="0 0 0"/>
    <geometry>
      <mesh filename="package://another_description/meshes/Left_Claw_v17_1.stl" scale="0.001 0.001 0.001"/>
    </geometry>
  </collision>
</link>

<link name="Right_Claw_v6_1">
  <inertial>
    <origin xyz="0.029511891745069047 -0.0016748855335407264 -0.005250768713266879" rpy="0 0 0"/>
    <mass value="0.11917653511717204"/>
    <inertia ixx="1.2e-05" iyy="3.2e-05" izz="2.5e-05" ixy="4e-06" iyz="-0.0" ixz="0.0"/>
  </inertial>
  <visual>
    <origin xyz="-0.1923 -0.058109 -0.176831" rpy="0 0 0"/>
    <geometry>
      <mesh filename="package://another_description/meshes/Right_Claw_v6_1.stl" scale="0.001 0.001 0.001"/>
    </geometry>
    <material name="steel_satin"/>
  </visual>
  <collision>
    <origin xyz="-0.1923 -0.058109 -0.176831" rpy="0 0 0"/>
    <geometry>
      <mesh filename="package://another_description/meshes/Right_Claw_v6_1.stl" scale="0.001 0.001 0.001"/>
    </geometry>
  </collision>
</link>

<link name="Helper_v12_1">
  <inertial>
    <origin xyz="2.5179922380491604e-07 0.01740487465200152 -0.0053215159135051315" rpy="0 0 0"/>
    <mass value="0.022811604845921114"/>
    <inertia ixx="3e-06" iyy="0.0" izz="3e-06" ixy="-0.0" iyz="0.0" ixz="-0.0"/>
  </inertial>
  <visual>
    <origin xyz="-0.220266 0.029577 -0.178446" rpy="0 0 0"/>
    <geometry>
      <mesh filename="package://another_description/meshes/Helper_v12_1.stl" scale="0.001 0.001 0.001"/>
    </geometry>
    <material name="steel_satin"/>
  </visual>
  <collision>
    <origin xyz="-0.220266 0.029577 -0.178446" rpy="0 0 0"/>
    <geometry>
      <mesh filename="package://another_description/meshes/Helper_v12_1.stl" scale="0.001 0.001 0.001"/>
    </geometry>
  </collision>
</link>

<link name="Helper_v12_2">
  <inertial>
    <origin xyz="1.3143032262519228e-07 -0.01758942262949937 -0.004677075576347112" rpy="0 0 0"/>
    <mass value="0.022811604845921114"/>
    <inertia ixx="3e-06" iyy="0.0" izz="3e-06" ixy="0.0" iyz="0.0" ixz="0.0"/>
  </inertial>
  <visual>
    <origin xyz="-0.220266 -0.05367 -0.176913" rpy="0 0 0"/>
    <geometry>
      <mesh filename="package://another_description/meshes/Helper_v12_2.stl" scale="0.001 0.001 0.001"/>
    </geometry>
    <material name="steel_satin"/>
  </visual>
  <collision>
    <origin xyz="-0.220266 -0.05367 -0.176913" rpy="0 0 0"/>
    <geometry>
      <mesh filename="package://another_description/meshes/Helper_v12_2.stl" scale="0.001 0.001 0.001"/>
    </geometry>
  </collision>
</link>

<joint name="Revolute 1" type="revolute">
  <origin xyz="0.030261 0.04575 0.01115" rpy="0 0 0"/>
  <parent link="base_link"/>
  <child link="new_lower_arm_v6_1"/>
  <axis xyz="-0.0 1.0 -0.0"/>
  <limit upper="-1.5707963268" lower="1.5707963268" effort="100" velocity="100"/>
</joint>

<joint name="Revolute 3" type="revolute">
  <origin xyz="0.0 0.0 0.12" rpy="0 0 0"/>
  <parent link="new_lower_arm_v6_1"/>
  <child link="another_together_v2_1"/>
  <axis xyz="-0.0 1.0 -0.0"/>
    <limit upper="-1.5707963268" lower="1.5707963268" effort="100" velocity="100"/>
</joint>

<joint name="Revolute 4" type="revolute">
  <origin xyz="0.022 -0.037448 0.0566" rpy="0 0 0"/>
  <parent link="another_together_v2_1"/>
  <child link="another_forearm_v1_1"/>
  <axis xyz="1.0 -0.0 0.0"/>
    <limit upper="-1.5707963268" lower="1.5707963268" effort="100" velocity="100"/>
</joint>

<joint name="Rigid 8" type="fixed">
  <origin xyz="0.0 0.0 0.0" rpy="0 0 0"/>
  <parent link="new_lower_arm_v6_1"/>
  <child link="lower_arm_pot_v5_1"/>
</joint>

<joint name="Revolute 9" type="revolute">
  <origin xyz="0.087939 -0.026995 0.000497" rpy="0 0 0"/>
  <parent link="another_forearm_v1_1"/>
  <child link="bottom_v2_1"/>
  <axis xyz="-0.0 -0.99983 0.018412"/>
    <limit upper="-1.5707963268" lower="1.5707963268" effort="100" velocity="100"/>
</joint>

<joint name="Revolute 10" type="continuous">
  <origin xyz="0.0521 0.041808 -0.010771" rpy="0 0 0"/>
  <parent link="bottom_v2_1"/>
  <child link="Jaw_top_v27_1"/>
  <axis xyz="-0.0 0.018412 0.99983"/>
</joint>

<joint name="Revolute 11" type="continuous">
  <origin xyz="0.0521 0.020757 -0.013384" rpy="0 0 0"/>
  <parent link="bottom_v2_1"/>
  <child link="Jaw_top_v23_1"/>
  <axis xyz="0.0 -0.018412 -0.99983"/>
</joint>

<joint name="Revolute 12" type="continuous">
  <origin xyz="0.0 -0.036081 0.003665" rpy="0 0 0"/>
  <parent link="Jaw_top_v23_1"/>
  <child link="Left_Claw_v17_1"/>
  <axis xyz="-0.0 0.018412 0.99983"/>
</joint>

<joint name="Revolute 13" type="continuous">
  <origin xyz="0.0 0.034994 -0.000645" rpy="0 0 0"/>
  <parent link="Jaw_top_v27_1"/>
  <child link="Right_Claw_v6_1"/>
  <axis xyz="-0.0 0.018412 0.99983"/>
</joint>

<joint name="Revolute 16" type="continuous">
  <origin xyz="0.027966 0.00444 -8.2e-05" rpy="0 0 0"/>
  <parent link="Left_Claw_v17_1"/>
  <child link="Helper_v12_1"/>
  <axis xyz="0.0 -0.018412 -0.99983"/>
</joint>

<joint name="Revolute 17" type="continuous">
  <origin xyz="0.027966 -0.004439 8.2e-05" rpy="0 0 0"/>
  <parent link="Right_Claw_v6_1"/>
  <child link="Helper_v12_2"/>
  <axis xyz="0.0 -0.018412 -0.99983"/>
</joint>

</robot>
